<mujoco model="humanoid">
  <compiler coordinate="local"/>
  <default>
    <joint damping="0.0" armature="0.01" stiffness="0.0" limited="true"/>
    <geom conaffinity="1" condim="3" contype="7" margin="0.001" rgba="0.8 0.6 .4 1"/>
  </default>
  <asset>
    <texture type="skybox" builtin="gradient" rgb1=".4 .5 .6" rgb2="0 0 0" width="100" height="100"/>
    <texture builtin="flat" height="1278" mark="cross" markrgb="1 1 1" name="texgeom" random="0.01" rgb1="0.8 0.6 0.4" rgb2="0.8 0.6 0.4" type="cube" width="127"/>
    <texture builtin="checker" height="100" name="texplane" rgb1="0 0 0" rgb2="0.8 0.8 0.8" type="2d" width="100"/>
    <material name="MatPlane" reflectance="0.5" shininess="1" specular="1" texrepeat="60 60" texture="texplane"/>
    <material name="geom" texture="texgeom" texuniform="true"/>
  </asset>
  <worldbody>
    <light cutoff="100" diffuse="1 1 1" dir="-0 0 -1.3" directional="true" exponent="1" pos="0 0 1.3" specular=".1 .1 .1"/>
    <geom conaffinity="1" condim="3" name="floor" pos="0 0 0" rgba="0.8 0.9 0.8 1" size="100 100 .2" type="plane" material="MatPlane"/>
    <body name="Pelvis" pos="-0.0019 -0.2253 0.0285">
      <freejoint name="Pelvis"/>
      <geom type="sphere" contype="1" conaffinity="1" density="4629.6296296296305" size="0.0948" pos="0.0000 0.0000 0.0000" name="Pelvis"/>
      <body name="L_Hip" pos="-0.0067 0.0696 -0.092">
        <joint name="L_Hip_x" type="hinge" pos="0 0 0" axis="1 0 0" user="250 2.5 1 500 10 2" armature="0.01" range="-90.0000 90.0000" damping="0" stiffness="0"/>
        <joint name="L_Hip_y" type="hinge" pos="0 0 0" axis="0 1 0" user="250 2.5 1 500 10 2" armature="0.01" range="-90.0000 90.0000" damping="0" stiffness="0"/>
        <joint name="L_Hip_z" type="hinge" pos="0 0 0" axis="0 0 1" user="250 2.5 1 500 10 2" armature="0.01" range="-90.0000 90.0000" damping="0" stiffness="0"/>
        <geom type="capsule" contype="1" conaffinity="1" density="2040.816327" fromto="-0.0009 0.0070 -0.0757 -0.0035 0.0279 -0.3028" size="0.0618" name="L_Hip"/>
        <body name="L_Knee" pos="-0.0043 0.0349 -0.3785">
          <joint name="L_Knee_x" type="hinge" pos="0 0 0" axis="1 0 0" user="250 2.5 1 500 10 2" armature="0.01" range="-5.6250 5.6250" damping="0" stiffness="0"/>
          <joint name="L_Knee_y" type="hinge" pos="0 0 0" axis="0 1 0" user="250 2.5 1 500 10 2" armature="0.01" range="0.0000 180.0000" damping="0" stiffness="0"/>
          <joint name="L_Knee_z" type="hinge" pos="0 0 0" axis="0 0 1" user="250 2.5 1 500 10 2" armature="0.01" range="-5.6250 5.6250" damping="0" stiffness="0"/>
          <geom type="capsule" contype="1" conaffinity="1" density="1234.567901" fromto="-0.0088 -0.0028 -0.0804 -0.0352 -0.0111 -0.3218" size="0.0544" name="L_Knee"/>
          <body name="L_Ankle" pos="-0.044 -0.0139 -0.4022">
            <joint name="L_Ankle_x" type="hinge" pos="0 0 0" axis="1 0 0" user="150 2.5 1 500 10 2" armature="0.01" range="-45.0000 45.0000" damping="0" stiffness="0"/>
            <joint name="L_Ankle_y" type="hinge" pos="0 0 0" axis="0 1 0" user="150 2.5 1 500 10 2" armature="0.01" range="-90.0000 90.0000" damping="0" stiffness="0"/>
            <joint name="L_Ankle_z" type="hinge" pos="0 0 0" axis="0 0 1" user="150 2.5 1 500 10 2" armature="0.01" range="-45.0000 45.0000" damping="0" stiffness="0"/>
            <geom type="box" density="449.066911" pos="0.0244 0.0237 -0.0240" size="0.0857 0.0488 0.0468" quat="1.0000 0.0000 0.0000 0.0000" name="L_Ankle"/>
            <body name="L_Toe" pos="0.1204 0.0268 -0.0563">
              <joint name="L_Toe_x" type="hinge" pos="0 0 0" axis="1 0 0" user="150 1 1 500 1 1" armature="0.01" range="-180.0000 180.0000" damping="0" stiffness="0"/>
              <joint name="L_Toe_y" type="hinge" pos="0 0 0" axis="0 1 0" user="150 1 1 500 1 1" armature="0.01" range="-180.0000 180.0000" damping="0" stiffness="0"/>
              <joint name="L_Toe_z" type="hinge" pos="0 0 0" axis="0 0 1" user="150 1 1 500 1 1" armature="0.01" range="-180.0000 180.0000" damping="0" stiffness="0"/>
              <geom type="box" density="424.15414" pos="0.0251 -0.0031 0.0055" size="0.05 0.0481 0.0202" quat="1.0000 0.0000 0.0000 0.0000" name="L_Toe"/>
            </body>
          </body>
        </body>
      </body>
      <body name="R_Hip" pos="-0.0042 -0.0678 -0.0911">
        <joint name="R_Hip_x" type="hinge" pos="0 0 0" axis="1 0 0" user="250 2.5 1 500 10 2" armature="0.01" range="-90.0000 90.0000" damping="0" stiffness="0"/>
        <joint name="R_Hip_y" type="hinge" pos="0 0 0" axis="0 1 0" user="250 2.5 1 500 10 2" armature="0.01" range="-90.0000 90.0000" damping="0" stiffness="0"/>
        <joint name="R_Hip_z" type="hinge" pos="0 0 0" axis="0 0 1" user="250 2.5 1 500 10 2" armature="0.01" range="-90.0000 90.0000" damping="0" stiffness="0"/>
        <geom type="capsule" contype="1" conaffinity="1" density="2040.816327" fromto="-0.0018 -0.0078 -0.0772 -0.0071 -0.0311 -0.3088" size="0.0608" name="R_Hip"/>
        <body name="R_Knee" pos="-0.0089 -0.0388 -0.3861">
          <joint name="R_Knee_x" type="hinge" pos="0 0 0" axis="1 0 0" user="250 2.5 1 500 10 2" armature="0.01" range="-5.6250 5.6250" damping="0" stiffness="0"/>
          <joint name="R_Knee_y" type="hinge" pos="0 0 0" axis="0 1 0" user="250 2.5 1 500 10 2" armature="0.01" range="0.0000 180.0000" damping="0" stiffness="0"/>
          <joint name="R_Knee_z" type="hinge" pos="0 0 0" axis="0 0 1" user="250 2.5 1 500 10 2" armature="0.01" range="-5.6250 5.6250" damping="0" stiffness="0"/>
          <geom type="capsule" contype="1" conaffinity="1" density="1234.567901" fromto="-0.0085 0.0032 -0.0806 -0.0341 0.0129 -0.3222" size="0.0545" name="R_Knee"/>
          <body name="R_Ankle" pos="-0.0426 0.0161 -0.4028">
            <joint name="R_Ankle_x" type="hinge" pos="0 0 0" axis="1 0 0" user="150 1 1 500 10 2" armature="0.01" range="-45.0000 45.0000" damping="0" stiffness="0"/>
            <joint name="R_Ankle_y" type="hinge" pos="0 0 0" axis="0 1 0" user="150 1 1 500 10 2" armature="0.01" range="-90.0000 90.0000" damping="0" stiffness="0"/>
            <joint name="R_Ankle_z" type="hinge" pos="0 0 0" axis="0 0 1" user="150 1 1 500 10 2" armature="0.01" range="-45.0000 45.0000" damping="0" stiffness="0"/>
            <geom type="box" density="435.148305" pos="0.0259 -0.0217 -0.0176" size="0.0873 0.0487 0.0483" quat="1.0000 0.0000 0.0000 0.0000" name="R_Ankle"/>
            <body name="R_Toe" pos="0.1245 -0.026 -0.0486">
              <joint name="R_Toe_x" type="hinge" pos="0 0 0" axis="1 0 0" user="150 1 1 500 1 1" armature="0.01" range="-180.0000 180.0000" damping="0" stiffness="0"/>
              <joint name="R_Toe_y" type="hinge" pos="0 0 0" axis="0 1 0" user="150 1 1 500 1 1" armature="0.01" range="-180.0000 180.0000" damping="0" stiffness="0"/>
              <joint name="R_Toe_z" type="hinge" pos="0 0 0" axis="0 0 1" user="150 1 1 500 1 1" armature="0.01" range="-180.0000 180.0000" damping="0" stiffness="0"/>
              <geom type="box" density="409.981889" pos="0.0228 0.0043 0.0045" size="0.0497 0.0483 0.0217" quat="1.0000 0.0000 0.0000 0.0000" name="R_Toe"/>
            </body>
          </body>
        </body>
      </body>
      <body name="Torso" pos="-0.0274 -0.0025 0.1101">
        <joint name="Torso_x" type="hinge" pos="0 0 0" axis="1 0 0" user="500 5 1 500 10 2" armature="0.01" range="-60.0000 60.0000" damping="0" stiffness="0"/>
        <joint name="Torso_y" type="hinge" pos="0 0 0" axis="0 1 0" user="500 5 1 500 10 2" armature="0.01" range="-60.0000 60.0000" damping="0" stiffness="0"/>
        <joint name="Torso_z" type="hinge" pos="0 0 0" axis="0 0 1" user="500 5 1 500 10 2" armature="0.01" range="-60.0000 60.0000" damping="0" stiffness="0"/>
        <geom type="capsule" contype="1" conaffinity="1" density="2040.816327" fromto="0.0006 0.0026 0.0614 0.0008 0.0031 0.0751" size="0.0778" name="Torso"/>
        <body name="Spine" pos="0.0014 0.0057 0.1365">
          <joint name="Spine_x" type="hinge" pos="0 0 0" axis="1 0 0" user="500 5 1 500 10 2" armature="0.01" range="-60.0000 60.0000" damping="0" stiffness="0"/>
          <joint name="Spine_y" type="hinge" pos="0 0 0" axis="0 1 0" user="500 5 1 500 10 2" armature="0.01" range="-60.0000 60.0000" damping="0" stiffness="0"/>
          <joint name="Spine_z" type="hinge" pos="0 0 0" axis="0 0 1" user="500 5 1 500 10 2" armature="0.01" range="-60.0000 60.0000" damping="0" stiffness="0"/>
          <geom type="capsule" contype="1" conaffinity="1" density="2040.816327" fromto="0.0114 0.0006 0.0241 0.0139 0.0008 0.0295" size="0.0762" name="Spine"/>
          <body name="Chest" pos="0.0253 0.0014 0.0535">
            <joint name="Chest_x" type="hinge" pos="0 0 0" axis="1 0 0" user="500 5 1 500 10 2" armature="0.01" range="-60.0000 60.0000" damping="0" stiffness="0"/>
            <joint name="Chest_y" type="hinge" pos="0 0 0" axis="0 1 0" user="500 5 1 500 10 2" armature="0.01" range="-60.0000 60.0000" damping="0" stiffness="0"/>
            <joint name="Chest_z" type="hinge" pos="0 0 0" axis="0 0 1" user="500 5 1 500 10 2" armature="0.01" range="-60.0000 60.0000" damping="0" stiffness="0"/>
            <geom type="capsule" contype="1" conaffinity="1" density="2040.816327" fromto="-0.0172 -0.0009 0.0687 -0.0210 -0.0011 0.0840" size="0.101" name="Chest"/>
            <body name="Neck" pos="-0.0422 -0.0029 0.2156">
              <joint name="Neck_x" type="hinge" pos="0 0 0" axis="1 0 0" user="150 1 1 250 50 4" armature="0.01" range="-5.6250 5.6250" damping="0" stiffness="0"/>
              <joint name="Neck_y" type="hinge" pos="0 0 0" axis="0 1 0" user="150 1 1 250 50 4" armature="0.01" range="-90.0000 90.0000" damping="0" stiffness="0"/>
              <joint name="Neck_z" type="hinge" pos="0 0 0" axis="0 0 1" user="150 1 1 250 50 4" armature="0.01" range="-90.0000 90.0000" damping="0" stiffness="0"/>
              <geom type="capsule" contype="1" conaffinity="1" density="1000" fromto="0.0103 0.0011 0.0131 0.0414 0.0043 0.0524" size="0.044" name="Neck"/>
              <body name="Head" pos="0.0517 0.0053 0.0655">
                <joint name="Head_x" type="hinge" pos="0 0 0" axis="1 0 0" user="150 1 1 250 50 4" armature="0.01" range="-5.6250 5.6250" damping="0" stiffness="0"/>
                <joint name="Head_y" type="hinge" pos="0 0 0" axis="0 1 0" user="150 1 1 250 50 4" armature="0.01" range="-90.0000 90.0000" damping="0" stiffness="0"/>
                <joint name="Head_z" type="hinge" pos="0 0 0" axis="0 0 1" user="150 1 1 250 50 4" armature="0.01" range="-90.0000 90.0000" damping="0" stiffness="0"/>
                <geom type="sphere" contype="1" conaffinity="1" density="1000" size="0.1016" pos="0.0000 0.0000 0.0000" name="Head"/>
              </body>
            </body>
            <body name="L_Thorax" pos="-0.0339 0.0795 0.1228">
              <joint name="L_Thorax_x" type="hinge" pos="0 0 0" axis="1 0 0" user="200 2 1 500 50 4" armature="0.01" range="-5.6250 5.6250" damping="0" stiffness="0"/>
              <joint name="L_Thorax_y" type="hinge" pos="0 0 0" axis="0 1 0" user="200 2 1 500 50 4" armature="0.01" range="-5.6250 5.6250" damping="0" stiffness="0"/>
              <joint name="L_Thorax_z" type="hinge" pos="0 0 0" axis="0 0 1" user="200 2 1 500 50 4" armature="0.01" range="-5.6250 5.6250" damping="0" stiffness="0"/>
              <geom type="capsule" contype="1" conaffinity="1" density="1000" fromto="-0.0018 0.0184 0.0061 -0.0073 0.0735 0.0244" size="0.0526" name="L_Thorax"/>
              <body name="L_Shoulder" pos="-0.0091 0.0918 0.0305">
                <joint name="L_Shoulder_x" type="hinge" pos="0 0 0" axis="1 0 0" user="200 2 1 500 50 4" armature="0.01" range="-720.0000 720.0000" damping="0" stiffness="0"/>
                <joint name="L_Shoulder_y" type="hinge" pos="0 0 0" axis="0 1 0" user="200 2 1 500 50 4" armature="0.01" range="-720.0000 720.0000" damping="0" stiffness="0"/>
                <joint name="L_Shoulder_z" type="hinge" pos="0 0 0" axis="0 0 1" user="200 2 1 500 50 4" armature="0.01" range="-720.0000 720.0000" damping="0" stiffness="0"/>
                <geom type="capsule" contype="1" conaffinity="1" density="1000" fromto="-0.0055 0.0524 -0.0026 -0.0221 0.2096 -0.0105" size="0.0522" name="L_Shoulder"/>
                <body name="L_Elbow" pos="-0.0276 0.262 -0.0131">
                  <joint name="L_Elbow_x" type="hinge" pos="0 0 0" axis="1 0 0" user="150 1 1 150 10 2" armature="0.01" range="-5.6250 5.6250" damping="0" stiffness="0"/>
                  <joint name="L_Elbow_y" type="hinge" pos="0 0 0" axis="0 1 0" user="150 1 1 150 10 2" armature="0.01" range="-5.6250 5.6250" damping="0" stiffness="0"/>
                  <joint name="L_Elbow_z" type="hinge" pos="0 0 0" axis="0 0 1" user="150 1 1 150 10 2" armature="0.01" range="-180.0000 0.0000" damping="0" stiffness="0"/>
                  <geom type="capsule" contype="1" conaffinity="1" density="1000" fromto="-0.0003 0.0504 0.0018 -0.0010 0.2015 0.0073" size="0.0408" name="L_Elbow"/>
                  <body name="L_Wrist" pos="-0.0013 0.2518 0.0091">
                    <joint name="L_Wrist_x" type="hinge" pos="0 0 0" axis="1 0 0" user="100 1 1 150 1 1" armature="0.01" range="-180.0000 180.0000" damping="0" stiffness="0"/>
                    <joint name="L_Wrist_y" type="hinge" pos="0 0 0" axis="0 1 0" user="100 1 1 150 1 1" armature="0.01" range="-180.0000 180.0000" damping="0" stiffness="0"/>
                    <joint name="L_Wrist_z" type="hinge" pos="0 0 0" axis="0 0 1" user="100 1 1 150 1 1" armature="0.01" range="-180.0000 180.0000" damping="0" stiffness="0"/>
                    <geom type="capsule" contype="1" conaffinity="1" density="1000" fromto="-0.0030 0.0170 -0.0016 -0.0122 0.0679 -0.0064" size="0.0321" name="L_Wrist"/>
                    <body name="L_Hand" pos="-0.0152 0.0849 -0.008">
                      <joint name="L_Hand_x" type="hinge" pos="0 0 0" axis="1 0 0" user="50 1 1 150 1 1" armature="0.01" range="-180.0000 180.0000" damping="0" stiffness="0"/>
                      <joint name="L_Hand_y" type="hinge" pos="0 0 0" axis="0 1 0" user="50 1 1 150 1 1" armature="0.01" range="-180.0000 180.0000" damping="0" stiffness="0"/>
                      <joint name="L_Hand_z" type="hinge" pos="0 0 0" axis="0 0 1" user="50 1 1 150 1 1" armature="0.01" range="-180.0000 180.0000" damping="0" stiffness="0"/>
                      <geom type="box" density="401.53505" pos="-0.0057 0.0498 0.0010" size="0.0543 0.0589 0.016" quat="1.0000 0.0000 0.0000 0.0000" name="L_Hand"/>
                    </body>
                  </body>
                </body>
              </body>
            </body>
            <body name="R_Thorax" pos="-0.0384 -0.0826 0.1197">
              <joint name="R_Thorax_x" type="hinge" pos="0 0 0" axis="1 0 0" user="200 2 1 150 10 2" armature="0.01" range="-5.6250 5.6250" damping="0" stiffness="0"/>
              <joint name="R_Thorax_y" type="hinge" pos="0 0 0" axis="0 1 0" user="200 2 1 150 10 2" armature="0.01" range="-5.6250 5.6250" damping="0" stiffness="0"/>
              <joint name="R_Thorax_z" type="hinge" pos="0 0 0" axis="0 0 1" user="200 2 1 150 10 2" armature="0.01" range="-5.6250 5.6250" damping="0" stiffness="0"/>
              <geom type="capsule" contype="1" conaffinity="1" density="1000" fromto="-0.0018 -0.0194 0.0065 -0.0072 -0.0776 0.0262" size="0.0516" name="R_Thorax"/>
              <body name="R_Shoulder" pos="-0.009 -0.097 0.0327">
                <joint name="R_Shoulder_x" type="hinge" pos="0 0 0" axis="1 0 0" user="200 2 1 250 10 2" armature="0.01" range="-720.0000 720.0000" damping="0" stiffness="0"/>
                <joint name="R_Shoulder_y" type="hinge" pos="0 0 0" axis="0 1 0" user="200 2 1 250 10 2" armature="0.01" range="-720.0000 720.0000" damping="0" stiffness="0"/>
                <joint name="R_Shoulder_z" type="hinge" pos="0 0 0" axis="0 0 1" user="200 2 1 250 10 2" armature="0.01" range="-720.0000 720.0000" damping="0" stiffness="0"/>
                <geom type="capsule" contype="1" conaffinity="1" density="1000" fromto="-0.0043 -0.0512 -0.0027 -0.0174 -0.2049 -0.0109" size="0.0536" name="R_Shoulder"/>
                <body name="R_Elbow" pos="-0.0217 -0.2561 -0.0136">
                  <joint name="R_Elbow_x" type="hinge" pos="0 0 0" axis="1 0 0" user="150 1 1 150 10 2" armature="0.01" range="-5.6250 5.6250" damping="0" stiffness="0"/>
                  <joint name="R_Elbow_y" type="hinge" pos="0 0 0" axis="0 1 0" user="150 1 1 150 10 2" armature="0.01" range="-5.6250 5.6250" damping="0" stiffness="0"/>
                  <joint name="R_Elbow_z" type="hinge" pos="0 0 0" axis="0 0 1" user="150 1 1 150 10 2" armature="0.01" range="0.0000 180.0000" damping="0" stiffness="0"/>
                  <geom type="capsule" contype="1" conaffinity="1" density="1000" fromto="-0.0012 -0.0516 0.0016 -0.0046 -0.2063 0.0062" size="0.0412" name="R_Elbow"/>
                  <body name="R_Wrist" pos="-0.0058 -0.2578 0.0078">
                    <joint name="R_Wrist_x" type="hinge" pos="0 0 0" axis="1 0 0" user="100 1 1 150 1 1" armature="0.01" range="-180.0000 180.0000" damping="0" stiffness="0"/>
                    <joint name="R_Wrist_y" type="hinge" pos="0 0 0" axis="0 1 0" user="100 1 1 150 1 1" armature="0.01" range="-180.0000 180.0000" damping="0" stiffness="0"/>
                    <joint name="R_Wrist_z" type="hinge" pos="0 0 0" axis="0 0 1" user="100 1 1 150 1 1" armature="0.01" range="-180.0000 180.0000" damping="0" stiffness="0"/>
                    <geom type="capsule" contype="1" conaffinity="1" density="1000" fromto="-0.0021 -0.0171 -0.0012 -0.0083 -0.0684 -0.0048" size="0.0329" name="R_Wrist"/>
                    <body name="R_Hand" pos="-0.0104 -0.0855 -0.006">
                      <joint name="R_Hand_x" type="hinge" pos="0 0 0" axis="1 0 0" user="50 1 1 150 1 1" armature="0.01" range="-180.0000 180.0000" damping="0" stiffness="0"/>
                      <joint name="R_Hand_y" type="hinge" pos="0 0 0" axis="0 1 0" user="50 1 1 150 1 1" armature="0.01" range="-180.0000 180.0000" damping="0" stiffness="0"/>
                      <joint name="R_Hand_z" type="hinge" pos="0 0 0" axis="0 0 1" user="50 1 1 150 1 1" armature="0.01" range="-180.0000 180.0000" damping="0" stiffness="0"/>
                      <geom type="box" density="404.547781" pos="-0.0080 -0.0466 -0.0009" size="0.0551 0.0574 0.0165" quat="1.0000 0.0000 0.0000 0.0000" name="R_Hand"/>
                    </body>
                  </body>
                </body>
              </body>
            </body>
          </body>
        </body>
      </body>
    </body>
  </worldbody>
  <actuator>
    <motor name="L_Hip_x" joint="L_Hip_x" gear="1"/>
    <motor name="L_Hip_y" joint="L_Hip_y" gear="1"/>
    <motor name="L_Hip_z" joint="L_Hip_z" gear="1"/>
    <motor name="L_Knee_x" joint="L_Knee_x" gear="1"/>
    <motor name="L_Knee_y" joint="L_Knee_y" gear="1"/>
    <motor name="L_Knee_z" joint="L_Knee_z" gear="1"/>
    <motor name="L_Ankle_x" joint="L_Ankle_x" gear="1"/>
    <motor name="L_Ankle_y" joint="L_Ankle_y" gear="1"/>
    <motor name="L_Ankle_z" joint="L_Ankle_z" gear="1"/>
    <motor name="L_Toe_x" joint="L_Toe_x" gear="1"/>
    <motor name="L_Toe_y" joint="L_Toe_y" gear="1"/>
    <motor name="L_Toe_z" joint="L_Toe_z" gear="1"/>
    <motor name="R_Hip_x" joint="R_Hip_x" gear="1"/>
    <motor name="R_Hip_y" joint="R_Hip_y" gear="1"/>
    <motor name="R_Hip_z" joint="R_Hip_z" gear="1"/>
    <motor name="R_Knee_x" joint="R_Knee_x" gear="1"/>
    <motor name="R_Knee_y" joint="R_Knee_y" gear="1"/>
    <motor name="R_Knee_z" joint="R_Knee_z" gear="1"/>
    <motor name="R_Ankle_x" joint="R_Ankle_x" gear="1"/>
    <motor name="R_Ankle_y" joint="R_Ankle_y" gear="1"/>
    <motor name="R_Ankle_z" joint="R_Ankle_z" gear="1"/>
    <motor name="R_Toe_x" joint="R_Toe_x" gear="1"/>
    <motor name="R_Toe_y" joint="R_Toe_y" gear="1"/>
    <motor name="R_Toe_z" joint="R_Toe_z" gear="1"/>
    <motor name="Torso_x" joint="Torso_x" gear="1"/>
    <motor name="Torso_y" joint="Torso_y" gear="1"/>
    <motor name="Torso_z" joint="Torso_z" gear="1"/>
    <motor name="Spine_x" joint="Spine_x" gear="1"/>
    <motor name="Spine_y" joint="Spine_y" gear="1"/>
    <motor name="Spine_z" joint="Spine_z" gear="1"/>
    <motor name="Chest_x" joint="Chest_x" gear="1"/>
    <motor name="Chest_y" joint="Chest_y" gear="1"/>
    <motor name="Chest_z" joint="Chest_z" gear="1"/>
    <motor name="Neck_x" joint="Neck_x" gear="1"/>
    <motor name="Neck_y" joint="Neck_y" gear="1"/>
    <motor name="Neck_z" joint="Neck_z" gear="1"/>
    <motor name="Head_x" joint="Head_x" gear="1"/>
    <motor name="Head_y" joint="Head_y" gear="1"/>
    <motor name="Head_z" joint="Head_z" gear="1"/>
    <motor name="L_Thorax_x" joint="L_Thorax_x" gear="1"/>
    <motor name="L_Thorax_y" joint="L_Thorax_y" gear="1"/>
    <motor name="L_Thorax_z" joint="L_Thorax_z" gear="1"/>
    <motor name="L_Shoulder_x" joint="L_Shoulder_x" gear="1"/>
    <motor name="L_Shoulder_y" joint="L_Shoulder_y" gear="1"/>
    <motor name="L_Shoulder_z" joint="L_Shoulder_z" gear="1"/>
    <motor name="L_Elbow_x" joint="L_Elbow_x" gear="1"/>
    <motor name="L_Elbow_y" joint="L_Elbow_y" gear="1"/>
    <motor name="L_Elbow_z" joint="L_Elbow_z" gear="1"/>
    <motor name="L_Wrist_x" joint="L_Wrist_x" gear="1"/>
    <motor name="L_Wrist_y" joint="L_Wrist_y" gear="1"/>
    <motor name="L_Wrist_z" joint="L_Wrist_z" gear="1"/>
    <motor name="L_Hand_x" joint="L_Hand_x" gear="1"/>
    <motor name="L_Hand_y" joint="L_Hand_y" gear="1"/>
    <motor name="L_Hand_z" joint="L_Hand_z" gear="1"/>
    <motor name="R_Thorax_x" joint="R_Thorax_x" gear="1"/>
    <motor name="R_Thorax_y" joint="R_Thorax_y" gear="1"/>
    <motor name="R_Thorax_z" joint="R_Thorax_z" gear="1"/>
    <motor name="R_Shoulder_x" joint="R_Shoulder_x" gear="1"/>
    <motor name="R_Shoulder_y" joint="R_Shoulder_y" gear="1"/>
    <motor name="R_Shoulder_z" joint="R_Shoulder_z" gear="1"/>
    <motor name="R_Elbow_x" joint="R_Elbow_x" gear="1"/>
    <motor name="R_Elbow_y" joint="R_Elbow_y" gear="1"/>
    <motor name="R_Elbow_z" joint="R_Elbow_z" gear="1"/>
    <motor name="R_Wrist_x" joint="R_Wrist_x" gear="1"/>
    <motor name="R_Wrist_y" joint="R_Wrist_y" gear="1"/>
    <motor name="R_Wrist_z" joint="R_Wrist_z" gear="1"/>
    <motor name="R_Hand_x" joint="R_Hand_x" gear="1"/>
    <motor name="R_Hand_y" joint="R_Hand_y" gear="1"/>
    <motor name="R_Hand_z" joint="R_Hand_z" gear="1"/>
  </actuator>
  <contact>
    <exclude body1="Torso" body2="Chest"/>
    <exclude body1="Head" body2="Chest"/>
    <exclude body1="R_Knee" body2="R_Toe"/>
    <exclude body1="R_Knee" body2="L_Ankle"/>
    <exclude body1="R_Knee" body2="L_Toe"/>
    <exclude body1="L_Knee" body2="L_Toe"/>
    <exclude body1="L_Knee" body2="R_Ankle"/>
    <exclude body1="L_Knee" body2="R_Toe"/>
    <exclude body1="L_Shoulder" body2="Chest"/>
    <exclude body1="R_Shoulder" body2="Chest"/>
  </contact>
  <sensor/>
  <size njmax="700" nconmax="700"/>
</mujoco>
