<mujoco model="humanoid">
  <compiler coordinate="local"/>
  <default>
    <joint damping="0.0" armature="0.01" stiffness="0.0" limited="true"/>
    <geom conaffinity="1" condim="3" contype="7" margin="0.001" rgba="0.8 0.6 .4 1"/>
  </default>
  <asset>
    <texture type="skybox" builtin="gradient" rgb1=".4 .5 .6" rgb2="0 0 0" width="100" height="100"/>
    <texture builtin="flat" height="1278" mark="cross" markrgb="1 1 1" name="texgeom" random="0.01" rgb1="0.8 0.6 0.4" rgb2="0.8 0.6 0.4" type="cube" width="127"/>
    <texture builtin="checker" height="100" name="texplane" rgb1="0 0 0" rgb2="0.8 0.8 0.8" type="2d" width="100"/>
    <material name="MatPlane" reflectance="0.5" shininess="1" specular="1" texrepeat="60 60" texture="texplane"/>
    <material name="geom" texture="texgeom" texuniform="true"/>
  </asset>
  <worldbody>
    <light cutoff="100" diffuse="1 1 1" dir="-0 0 -1.3" directional="true" exponent="1" pos="0 0 1.3" specular=".1 .1 .1"/>
    <geom conaffinity="1" condim="3" name="floor" pos="0 0 0" rgba="0.8 0.9 0.8 1" size="100 100 .2" type="plane" material="MatPlane"/>
    <body name="Pelvis" pos="-0.0016 -0.1966 0.0209">
      <freejoint name="Pelvis"/>
      <geom type="sphere" contype="1" conaffinity="1" density="4629.6296296296305" size="0.0841" pos="0.0000 0.0000 0.0000" name="Pelvis"/>
      <body name="L_Hip" pos="-0.0101 0.0651 -0.0845">
        <joint name="L_Hip_x" type="hinge" pos="0 0 0" axis="1 0 0" user="250 2.5 1 500 10 2" armature="0.01" range="-90.0000 90.0000" damping="0" stiffness="0"/>
        <joint name="L_Hip_y" type="hinge" pos="0 0 0" axis="0 1 0" user="250 2.5 1 500 10 2" armature="0.01" range="-90.0000 90.0000" damping="0" stiffness="0"/>
        <joint name="L_Hip_z" type="hinge" pos="0 0 0" axis="0 0 1" user="250 2.5 1 500 10 2" armature="0.01" range="-90.0000 90.0000" damping="0" stiffness="0"/>
        <geom type="capsule" contype="1" conaffinity="1" density="2040.816327" fromto="-0.0005 0.0061 -0.0697 -0.0021 0.0245 -0.2786" size="0.0571" name="L_Hip"/>
        <body name="L_Knee" pos="-0.0026 0.0306 -0.3483">
          <joint name="L_Knee_x" type="hinge" pos="0 0 0" axis="1 0 0" user="250 2.5 1 500 10 2" armature="0.01" range="-5.6250 5.6250" damping="0" stiffness="0"/>
          <joint name="L_Knee_y" type="hinge" pos="0 0 0" axis="0 1 0" user="250 2.5 1 500 10 2" armature="0.01" range="0.0000 180.0000" damping="0" stiffness="0"/>
          <joint name="L_Knee_z" type="hinge" pos="0 0 0" axis="0 0 1" user="250 2.5 1 500 10 2" armature="0.01" range="-5.6250 5.6250" damping="0" stiffness="0"/>
          <geom type="capsule" contype="1" conaffinity="1" density="1234.567901" fromto="-0.0079 -0.0020 -0.0716 -0.0314 -0.0081 -0.2864" size="0.0489" name="L_Knee"/>
          <body name="L_Ankle" pos="-0.0393 -0.0101 -0.3579">
            <joint name="L_Ankle_x" type="hinge" pos="0 0 0" axis="1 0 0" user="150 2.5 1 500 10 2" armature="0.01" range="-45.0000 45.0000" damping="0" stiffness="0"/>
            <joint name="L_Ankle_y" type="hinge" pos="0 0 0" axis="0 1 0" user="150 2.5 1 500 10 2" armature="0.01" range="-90.0000 90.0000" damping="0" stiffness="0"/>
            <joint name="L_Ankle_z" type="hinge" pos="0 0 0" axis="0 0 1" user="150 2.5 1 500 10 2" armature="0.01" range="-45.0000 45.0000" damping="0" stiffness="0"/>
            <geom type="box" density="442.596608" pos="0.0218 0.0199 -0.0222" size="0.0769 0.0422 0.0415" quat="1.0000 0.0000 0.0000 0.0000" name="L_Ankle"/>
            <body name="L_Toe" pos="0.107 0.0222 -0.051">
              <joint name="L_Toe_x" type="hinge" pos="0 0 0" axis="1 0 0" user="150 1 1 500 1 1" armature="0.01" range="-180.0000 180.0000" damping="0" stiffness="0"/>
              <joint name="L_Toe_y" type="hinge" pos="0 0 0" axis="0 1 0" user="150 1 1 500 1 1" armature="0.01" range="-180.0000 180.0000" damping="0" stiffness="0"/>
              <joint name="L_Toe_z" type="hinge" pos="0 0 0" axis="0 0 1" user="150 1 1 500 1 1" armature="0.01" range="-180.0000 180.0000" damping="0" stiffness="0"/>
              <geom type="box" density="402.006298" pos="0.0224 -0.0023 0.0054" size="0.0447 0.0427 0.0181" quat="1.0000 0.0000 0.0000 0.0000" name="L_Toe"/>
            </body>
          </body>
        </body>
      </body>
      <body name="R_Hip" pos="-0.0068 -0.063 -0.0838">
        <joint name="R_Hip_x" type="hinge" pos="0 0 0" axis="1 0 0" user="250 2.5 1 500 10 2" armature="0.01" range="-90.0000 90.0000" damping="0" stiffness="0"/>
        <joint name="R_Hip_y" type="hinge" pos="0 0 0" axis="0 1 0" user="250 2.5 1 500 10 2" armature="0.01" range="-90.0000 90.0000" damping="0" stiffness="0"/>
        <joint name="R_Hip_z" type="hinge" pos="0 0 0" axis="0 0 1" user="250 2.5 1 500 10 2" armature="0.01" range="-90.0000 90.0000" damping="0" stiffness="0"/>
        <geom type="capsule" contype="1" conaffinity="1" density="2040.816327" fromto="-0.0011 -0.0070 -0.0707 -0.0042 -0.0279 -0.2828" size="0.0564" name="R_Hip"/>
        <body name="R_Knee" pos="-0.0053 -0.0348 -0.3535">
          <joint name="R_Knee_x" type="hinge" pos="0 0 0" axis="1 0 0" user="250 2.5 1 500 10 2" armature="0.01" range="-5.6250 5.6250" damping="0" stiffness="0"/>
          <joint name="R_Knee_y" type="hinge" pos="0 0 0" axis="0 1 0" user="250 2.5 1 500 10 2" armature="0.01" range="0.0000 180.0000" damping="0" stiffness="0"/>
          <joint name="R_Knee_z" type="hinge" pos="0 0 0" axis="0 0 1" user="250 2.5 1 500 10 2" armature="0.01" range="-5.6250 5.6250" damping="0" stiffness="0"/>
          <geom type="capsule" contype="1" conaffinity="1" density="1234.567901" fromto="-0.0076 0.0025 -0.0714 -0.0304 0.0100 -0.2858" size="0.0493" name="R_Knee"/>
          <body name="R_Ankle" pos="-0.038 0.0125 -0.3572">
            <joint name="R_Ankle_x" type="hinge" pos="0 0 0" axis="1 0 0" user="150 1 1 500 10 2" armature="0.01" range="-45.0000 45.0000" damping="0" stiffness="0"/>
            <joint name="R_Ankle_y" type="hinge" pos="0 0 0" axis="0 1 0" user="150 1 1 500 10 2" armature="0.01" range="-90.0000 90.0000" damping="0" stiffness="0"/>
            <joint name="R_Ankle_z" type="hinge" pos="0 0 0" axis="0 0 1" user="150 1 1 500 10 2" armature="0.01" range="-45.0000 45.0000" damping="0" stiffness="0"/>
            <geom type="box" density="427.230966" pos="0.0231 -0.0145 -0.0157" size="0.0781 0.0427 0.042" quat="1.0000 0.0000 0.0000 0.0000" name="R_Ankle"/>
            <body name="R_Toe" pos="0.11 -0.0176 -0.0427">
              <joint name="R_Toe_x" type="hinge" pos="0 0 0" axis="1 0 0" user="150 1 1 500 1 1" armature="0.01" range="-180.0000 180.0000" damping="0" stiffness="0"/>
              <joint name="R_Toe_y" type="hinge" pos="0 0 0" axis="0 1 0" user="150 1 1 500 1 1" armature="0.01" range="-180.0000 180.0000" damping="0" stiffness="0"/>
              <joint name="R_Toe_z" type="hinge" pos="0 0 0" axis="0 0 1" user="150 1 1 500 1 1" armature="0.01" range="-180.0000 180.0000" damping="0" stiffness="0"/>
              <geom type="box" density="367.430763" pos="0.0216 0.0032 0.0052" size="0.0445 0.0424 0.0203" quat="1.0000 0.0000 0.0000 0.0000" name="R_Toe"/>
            </body>
          </body>
        </body>
      </body>
      <body name="Torso" pos="-0.0165 -0.0024 0.0962">
        <joint name="Torso_x" type="hinge" pos="0 0 0" axis="1 0 0" user="500 5 1 500 10 2" armature="0.01" range="-60.0000 60.0000" damping="0" stiffness="0"/>
        <joint name="Torso_y" type="hinge" pos="0 0 0" axis="0 1 0" user="500 5 1 500 10 2" armature="0.01" range="-60.0000 60.0000" damping="0" stiffness="0"/>
        <joint name="Torso_z" type="hinge" pos="0 0 0" axis="0 0 1" user="500 5 1 500 10 2" armature="0.01" range="-60.0000 60.0000" damping="0" stiffness="0"/>
        <geom type="capsule" contype="1" conaffinity="1" density="2040.816327" fromto="-0.0004 0.0016 0.0559 -0.0005 0.0019 0.0684" size="0.064" name="Torso"/>
        <body name="Spine" pos="-0.0009 0.0035 0.1243">
          <joint name="Spine_x" type="hinge" pos="0 0 0" axis="1 0 0" user="500 5 1 500 10 2" armature="0.01" range="-60.0000 60.0000" damping="0" stiffness="0"/>
          <joint name="Spine_y" type="hinge" pos="0 0 0" axis="0 1 0" user="500 5 1 500 10 2" armature="0.01" range="-60.0000 60.0000" damping="0" stiffness="0"/>
          <joint name="Spine_z" type="hinge" pos="0 0 0" axis="0 0 1" user="500 5 1 500 10 2" armature="0.01" range="-60.0000 60.0000" damping="0" stiffness="0"/>
          <geom type="capsule" contype="1" conaffinity="1" density="2040.816327" fromto="0.0112 0.0010 0.0205 0.0137 0.0012 0.0251" size="0.0635" name="Spine"/>
          <body name="Chest" pos="0.0249 0.0022 0.0456">
            <joint name="Chest_x" type="hinge" pos="0 0 0" axis="1 0 0" user="500 5 1 500 10 2" armature="0.01" range="-60.0000 60.0000" damping="0" stiffness="0"/>
            <joint name="Chest_y" type="hinge" pos="0 0 0" axis="0 1 0" user="500 5 1 500 10 2" armature="0.01" range="-60.0000 60.0000" damping="0" stiffness="0"/>
            <joint name="Chest_z" type="hinge" pos="0 0 0" axis="0 0 1" user="500 5 1 500 10 2" armature="0.01" range="-60.0000 60.0000" damping="0" stiffness="0"/>
            <geom type="capsule" contype="1" conaffinity="1" density="2040.816327" fromto="-0.0172 -0.0005 0.0596 -0.0210 -0.0007 0.0729" size="0.0861" name="Chest"/>
            <body name="Neck" pos="-0.0431 -0.0021 0.1872">
              <joint name="Neck_x" type="hinge" pos="0 0 0" axis="1 0 0" user="150 1 1 250 50 4" armature="0.01" range="-5.6250 5.6250" damping="0" stiffness="0"/>
              <joint name="Neck_y" type="hinge" pos="0 0 0" axis="0 1 0" user="150 1 1 250 50 4" armature="0.01" range="-90.0000 90.0000" damping="0" stiffness="0"/>
              <joint name="Neck_z" type="hinge" pos="0 0 0" axis="0 0 1" user="150 1 1 250 50 4" armature="0.01" range="-90.0000 90.0000" damping="0" stiffness="0"/>
              <geom type="capsule" contype="1" conaffinity="1" density="1000" fromto="0.0096 0.0008 0.0120 0.0383 0.0031 0.0479" size="0.0374" name="Neck"/>
              <body name="Head" pos="0.0479 0.0039 0.0599">
                <joint name="Head_x" type="hinge" pos="0 0 0" axis="1 0 0" user="150 1 1 250 50 4" armature="0.01" range="-5.6250 5.6250" damping="0" stiffness="0"/>
                <joint name="Head_y" type="hinge" pos="0 0 0" axis="0 1 0" user="150 1 1 250 50 4" armature="0.01" range="-90.0000 90.0000" damping="0" stiffness="0"/>
                <joint name="Head_z" type="hinge" pos="0 0 0" axis="0 0 1" user="150 1 1 250 50 4" armature="0.01" range="-90.0000 90.0000" damping="0" stiffness="0"/>
                <geom type="sphere" contype="1" conaffinity="1" density="1000" size="0.0931" pos="0.0000 0.0000 0.0000" name="Head"/>
              </body>
            </body>
            <body name="L_Thorax" pos="-0.0334 0.0669 0.106">
              <joint name="L_Thorax_x" type="hinge" pos="0 0 0" axis="1 0 0" user="200 2 1 500 50 4" armature="0.01" range="-5.6250 5.6250" damping="0" stiffness="0"/>
              <joint name="L_Thorax_y" type="hinge" pos="0 0 0" axis="0 1 0" user="200 2 1 500 50 4" armature="0.01" range="-5.6250 5.6250" damping="0" stiffness="0"/>
              <joint name="L_Thorax_z" type="hinge" pos="0 0 0" axis="0 0 1" user="200 2 1 500 50 4" armature="0.01" range="-5.6250 5.6250" damping="0" stiffness="0"/>
              <geom type="capsule" contype="1" conaffinity="1" density="1000" fromto="-0.0010 0.0153 0.0059 -0.0041 0.0613 0.0235" size="0.0439" name="L_Thorax"/>
              <body name="L_Shoulder" pos="-0.0051 0.0767 0.0294">
                <joint name="L_Shoulder_x" type="hinge" pos="0 0 0" axis="1 0 0" user="200 2 1 500 50 4" armature="0.01" range="-720.0000 720.0000" damping="0" stiffness="0"/>
                <joint name="L_Shoulder_y" type="hinge" pos="0 0 0" axis="0 1 0" user="200 2 1 500 50 4" armature="0.01" range="-720.0000 720.0000" damping="0" stiffness="0"/>
                <joint name="L_Shoulder_z" type="hinge" pos="0 0 0" axis="0 0 1" user="200 2 1 500 50 4" armature="0.01" range="-720.0000 720.0000" damping="0" stiffness="0"/>
                <geom type="capsule" contype="1" conaffinity="1" density="1000" fromto="-0.0050 0.0464 -0.0020 -0.0200 0.1855 -0.0082" size="0.0439" name="L_Shoulder"/>
                <body name="L_Elbow" pos="-0.025 0.2318 -0.0102">
                  <joint name="L_Elbow_x" type="hinge" pos="0 0 0" axis="1 0 0" user="150 1 1 150 10 2" armature="0.01" range="-5.6250 5.6250" damping="0" stiffness="0"/>
                  <joint name="L_Elbow_y" type="hinge" pos="0 0 0" axis="0 1 0" user="150 1 1 150 10 2" armature="0.01" range="-5.6250 5.6250" damping="0" stiffness="0"/>
                  <joint name="L_Elbow_z" type="hinge" pos="0 0 0" axis="0 0 1" user="150 1 1 150 10 2" armature="0.01" range="-180.0000 0.0000" damping="0" stiffness="0"/>
                  <geom type="capsule" contype="1" conaffinity="1" density="1000" fromto="-0.0003 0.0442 0.0015 -0.0012 0.1767 0.0061" size="0.0348" name="L_Elbow"/>
                  <body name="L_Wrist" pos="-0.0015 0.2209 0.0077">
                    <joint name="L_Wrist_x" type="hinge" pos="0 0 0" axis="1 0 0" user="100 1 1 150 1 1" armature="0.01" range="-180.0000 180.0000" damping="0" stiffness="0"/>
                    <joint name="L_Wrist_y" type="hinge" pos="0 0 0" axis="0 1 0" user="100 1 1 150 1 1" armature="0.01" range="-180.0000 180.0000" damping="0" stiffness="0"/>
                    <joint name="L_Wrist_z" type="hinge" pos="0 0 0" axis="0 0 1" user="100 1 1 150 1 1" armature="0.01" range="-180.0000 180.0000" damping="0" stiffness="0"/>
                    <geom type="capsule" contype="1" conaffinity="1" density="1000" fromto="-0.0024 0.0146 -0.0019 -0.0096 0.0586 -0.0076" size="0.0276" name="L_Wrist"/>
                    <body name="L_Hand" pos="-0.012 0.0732 -0.0095">
                      <joint name="L_Hand_x" type="hinge" pos="0 0 0" axis="1 0 0" user="50 1 1 150 1 1" armature="0.01" range="-180.0000 180.0000" damping="0" stiffness="0"/>
                      <joint name="L_Hand_y" type="hinge" pos="0 0 0" axis="0 1 0" user="50 1 1 150 1 1" armature="0.01" range="-180.0000 180.0000" damping="0" stiffness="0"/>
                      <joint name="L_Hand_z" type="hinge" pos="0 0 0" axis="0 0 1" user="50 1 1 150 1 1" armature="0.01" range="-180.0000 180.0000" damping="0" stiffness="0"/>
                      <geom type="box" density="391.381314" pos="-0.0061 0.0438 0.0007" size="0.0473 0.0523 0.0141" quat="1.0000 0.0000 0.0000 0.0000" name="L_Hand"/>
                    </body>
                  </body>
                </body>
              </body>
            </body>
            <body name="R_Thorax" pos="-0.0381 -0.0684 0.1042">
              <joint name="R_Thorax_x" type="hinge" pos="0 0 0" axis="1 0 0" user="200 2 1 150 10 2" armature="0.01" range="-5.6250 5.6250" damping="0" stiffness="0"/>
              <joint name="R_Thorax_y" type="hinge" pos="0 0 0" axis="0 1 0" user="200 2 1 150 10 2" armature="0.01" range="-5.6250 5.6250" damping="0" stiffness="0"/>
              <joint name="R_Thorax_z" type="hinge" pos="0 0 0" axis="0 0 1" user="200 2 1 150 10 2" armature="0.01" range="-5.6250 5.6250" damping="0" stiffness="0"/>
              <geom type="capsule" contype="1" conaffinity="1" density="1000" fromto="-0.0017 -0.0161 0.0059 -0.0069 -0.0643 0.0235" size="0.043" name="R_Thorax"/>
              <body name="R_Shoulder" pos="-0.0086 -0.0803 0.0294">
                <joint name="R_Shoulder_x" type="hinge" pos="0 0 0" axis="1 0 0" user="200 2 1 250 10 2" armature="0.01" range="-720.0000 720.0000" damping="0" stiffness="0"/>
                <joint name="R_Shoulder_y" type="hinge" pos="0 0 0" axis="0 1 0" user="200 2 1 250 10 2" armature="0.01" range="-720.0000 720.0000" damping="0" stiffness="0"/>
                <joint name="R_Shoulder_z" type="hinge" pos="0 0 0" axis="0 0 1" user="200 2 1 250 10 2" armature="0.01" range="-720.0000 720.0000" damping="0" stiffness="0"/>
                <geom type="capsule" contype="1" conaffinity="1" density="1000" fromto="-0.0034 -0.0451 -0.0021 -0.0138 -0.1803 -0.0084" size="0.045" name="R_Shoulder"/>
                <body name="R_Elbow" pos="-0.0172 -0.2254 -0.0105">
                  <joint name="R_Elbow_x" type="hinge" pos="0 0 0" axis="1 0 0" user="150 1 1 150 10 2" armature="0.01" range="-5.6250 5.6250" damping="0" stiffness="0"/>
                  <joint name="R_Elbow_y" type="hinge" pos="0 0 0" axis="0 1 0" user="150 1 1 150 10 2" armature="0.01" range="-5.6250 5.6250" damping="0" stiffness="0"/>
                  <joint name="R_Elbow_z" type="hinge" pos="0 0 0" axis="0 0 1" user="150 1 1 150 10 2" armature="0.01" range="0.0000 180.0000" damping="0" stiffness="0"/>
                  <geom type="capsule" contype="1" conaffinity="1" density="1000" fromto="-0.0009 -0.0456 0.0015 -0.0034 -0.1824 0.0060" size="0.0347" name="R_Elbow"/>
                  <body name="R_Wrist" pos="-0.0043 -0.2281 0.0075">
                    <joint name="R_Wrist_x" type="hinge" pos="0 0 0" axis="1 0 0" user="100 1 1 150 1 1" armature="0.01" range="-180.0000 180.0000" damping="0" stiffness="0"/>
                    <joint name="R_Wrist_y" type="hinge" pos="0 0 0" axis="0 1 0" user="100 1 1 150 1 1" armature="0.01" range="-180.0000 180.0000" damping="0" stiffness="0"/>
                    <joint name="R_Wrist_z" type="hinge" pos="0 0 0" axis="0 0 1" user="100 1 1 150 1 1" armature="0.01" range="-180.0000 180.0000" damping="0" stiffness="0"/>
                    <geom type="capsule" contype="1" conaffinity="1" density="1000" fromto="-0.0019 -0.0147 -0.0014 -0.0077 -0.0589 -0.0056" size="0.0281" name="R_Wrist"/>
                    <body name="R_Hand" pos="-0.0096 -0.0736 -0.007">
                      <joint name="R_Hand_x" type="hinge" pos="0 0 0" axis="1 0 0" user="50 1 1 150 1 1" armature="0.01" range="-180.0000 180.0000" damping="0" stiffness="0"/>
                      <joint name="R_Hand_y" type="hinge" pos="0 0 0" axis="0 1 0" user="50 1 1 150 1 1" armature="0.01" range="-180.0000 180.0000" damping="0" stiffness="0"/>
                      <joint name="R_Hand_z" type="hinge" pos="0 0 0" axis="0 0 1" user="50 1 1 150 1 1" armature="0.01" range="-180.0000 180.0000" damping="0" stiffness="0"/>
                      <geom type="box" density="397.015715" pos="-0.0075 -0.0408 -0.0009" size="0.0476 0.0506 0.0143" quat="1.0000 0.0000 0.0000 0.0000" name="R_Hand"/>
                    </body>
                  </body>
                </body>
              </body>
            </body>
          </body>
        </body>
      </body>
    </body>
  </worldbody>
  <actuator>
    <motor name="L_Hip_x" joint="L_Hip_x" gear="1"/>
    <motor name="L_Hip_y" joint="L_Hip_y" gear="1"/>
    <motor name="L_Hip_z" joint="L_Hip_z" gear="1"/>
    <motor name="L_Knee_x" joint="L_Knee_x" gear="1"/>
    <motor name="L_Knee_y" joint="L_Knee_y" gear="1"/>
    <motor name="L_Knee_z" joint="L_Knee_z" gear="1"/>
    <motor name="L_Ankle_x" joint="L_Ankle_x" gear="1"/>
    <motor name="L_Ankle_y" joint="L_Ankle_y" gear="1"/>
    <motor name="L_Ankle_z" joint="L_Ankle_z" gear="1"/>
    <motor name="L_Toe_x" joint="L_Toe_x" gear="1"/>
    <motor name="L_Toe_y" joint="L_Toe_y" gear="1"/>
    <motor name="L_Toe_z" joint="L_Toe_z" gear="1"/>
    <motor name="R_Hip_x" joint="R_Hip_x" gear="1"/>
    <motor name="R_Hip_y" joint="R_Hip_y" gear="1"/>
    <motor name="R_Hip_z" joint="R_Hip_z" gear="1"/>
    <motor name="R_Knee_x" joint="R_Knee_x" gear="1"/>
    <motor name="R_Knee_y" joint="R_Knee_y" gear="1"/>
    <motor name="R_Knee_z" joint="R_Knee_z" gear="1"/>
    <motor name="R_Ankle_x" joint="R_Ankle_x" gear="1"/>
    <motor name="R_Ankle_y" joint="R_Ankle_y" gear="1"/>
    <motor name="R_Ankle_z" joint="R_Ankle_z" gear="1"/>
    <motor name="R_Toe_x" joint="R_Toe_x" gear="1"/>
    <motor name="R_Toe_y" joint="R_Toe_y" gear="1"/>
    <motor name="R_Toe_z" joint="R_Toe_z" gear="1"/>
    <motor name="Torso_x" joint="Torso_x" gear="1"/>
    <motor name="Torso_y" joint="Torso_y" gear="1"/>
    <motor name="Torso_z" joint="Torso_z" gear="1"/>
    <motor name="Spine_x" joint="Spine_x" gear="1"/>
    <motor name="Spine_y" joint="Spine_y" gear="1"/>
    <motor name="Spine_z" joint="Spine_z" gear="1"/>
    <motor name="Chest_x" joint="Chest_x" gear="1"/>
    <motor name="Chest_y" joint="Chest_y" gear="1"/>
    <motor name="Chest_z" joint="Chest_z" gear="1"/>
    <motor name="Neck_x" joint="Neck_x" gear="1"/>
    <motor name="Neck_y" joint="Neck_y" gear="1"/>
    <motor name="Neck_z" joint="Neck_z" gear="1"/>
    <motor name="Head_x" joint="Head_x" gear="1"/>
    <motor name="Head_y" joint="Head_y" gear="1"/>
    <motor name="Head_z" joint="Head_z" gear="1"/>
    <motor name="L_Thorax_x" joint="L_Thorax_x" gear="1"/>
    <motor name="L_Thorax_y" joint="L_Thorax_y" gear="1"/>
    <motor name="L_Thorax_z" joint="L_Thorax_z" gear="1"/>
    <motor name="L_Shoulder_x" joint="L_Shoulder_x" gear="1"/>
    <motor name="L_Shoulder_y" joint="L_Shoulder_y" gear="1"/>
    <motor name="L_Shoulder_z" joint="L_Shoulder_z" gear="1"/>
    <motor name="L_Elbow_x" joint="L_Elbow_x" gear="1"/>
    <motor name="L_Elbow_y" joint="L_Elbow_y" gear="1"/>
    <motor name="L_Elbow_z" joint="L_Elbow_z" gear="1"/>
    <motor name="L_Wrist_x" joint="L_Wrist_x" gear="1"/>
    <motor name="L_Wrist_y" joint="L_Wrist_y" gear="1"/>
    <motor name="L_Wrist_z" joint="L_Wrist_z" gear="1"/>
    <motor name="L_Hand_x" joint="L_Hand_x" gear="1"/>
    <motor name="L_Hand_y" joint="L_Hand_y" gear="1"/>
    <motor name="L_Hand_z" joint="L_Hand_z" gear="1"/>
    <motor name="R_Thorax_x" joint="R_Thorax_x" gear="1"/>
    <motor name="R_Thorax_y" joint="R_Thorax_y" gear="1"/>
    <motor name="R_Thorax_z" joint="R_Thorax_z" gear="1"/>
    <motor name="R_Shoulder_x" joint="R_Shoulder_x" gear="1"/>
    <motor name="R_Shoulder_y" joint="R_Shoulder_y" gear="1"/>
    <motor name="R_Shoulder_z" joint="R_Shoulder_z" gear="1"/>
    <motor name="R_Elbow_x" joint="R_Elbow_x" gear="1"/>
    <motor name="R_Elbow_y" joint="R_Elbow_y" gear="1"/>
    <motor name="R_Elbow_z" joint="R_Elbow_z" gear="1"/>
    <motor name="R_Wrist_x" joint="R_Wrist_x" gear="1"/>
    <motor name="R_Wrist_y" joint="R_Wrist_y" gear="1"/>
    <motor name="R_Wrist_z" joint="R_Wrist_z" gear="1"/>
    <motor name="R_Hand_x" joint="R_Hand_x" gear="1"/>
    <motor name="R_Hand_y" joint="R_Hand_y" gear="1"/>
    <motor name="R_Hand_z" joint="R_Hand_z" gear="1"/>
  </actuator>
  <contact>
    <exclude body1="Torso" body2="Chest"/>
    <exclude body1="Head" body2="Chest"/>
    <exclude body1="R_Knee" body2="R_Toe"/>
    <exclude body1="R_Knee" body2="L_Ankle"/>
    <exclude body1="R_Knee" body2="L_Toe"/>
    <exclude body1="L_Knee" body2="L_Toe"/>
    <exclude body1="L_Knee" body2="R_Ankle"/>
    <exclude body1="L_Knee" body2="R_Toe"/>
    <exclude body1="L_Shoulder" body2="Chest"/>
    <exclude body1="R_Shoulder" body2="Chest"/>
  </contact>
  <sensor/>
  <size njmax="700" nconmax="700"/>
</mujoco>
